<?xml version="1.0" encoding="UTF-8"?>
<testsuites>
  <testsuite errors="0" failures="0" tests="1" skipped="0" name="D:.fredgrttsstuff.GithubProjects.flutter_devops.basic_coverage.test.counter" timestamp="2021-08-18T20:33:08">
    <properties>
      <property name="platform" value="vm"/>
    </properties>
    <testcase classname="D:.fredgrttsstuff.GithubProjects.flutter_devops.basic_coverage.test.counter" name="Counter increments by one increment counter by one" time="2.56"/>
  </testsuite>
  <testsuite errors="0" failures="0" tests="2" skipped="0" name="D:.fredgrttsstuff.GithubProjects.flutter_devops.basic_coverage.test.golden_widget" timestamp="2021-08-18T20:33:08">
    <properties>
      <property name="platform" value="vm"/>
    </properties>
    <testcase classname="D:.fredgrttsstuff.GithubProjects.flutter_devops.basic_coverage.test.golden_widget" name="Basic Golden Tests  Golden test" time="2.707"/>
    <testcase classname="D:.fredgrttsstuff.GithubProjects.flutter_devops.basic_coverage.test.golden_widget" name="Basic Golden Tests  DeviceBuilder " time="0.752"/>
    <system-out>Warning: A tag was used that wasn't specified in dart_test.yaml.
  golden was used in the test "Basic Golden Tests  DeviceBuilder "
</system-out>
  </testsuite>
  <testsuite errors="2" failures="0" tests="3" skipped="0" name="D:.fredgrttsstuff.GithubProjects.flutter_devops.basic_coverage.test.my_home_page" timestamp="2021-08-18T20:33:08">
    <properties>
      <property name="platform" value="vm"/>
    </properties>
    <testcase classname="D:.fredgrttsstuff.GithubProjects.flutter_devops.basic_coverage.test.my_home_page" name="Has MyApp and App Title  My home widget has a title and message, using PageObject" time="1.825">
      <error message="1 error, see stacktrace for details">Error:\n\nTest failed. See exception logs above.
The test description was: My home widget has a title and message, using PageObject</error>
      <system-out>????????? EXCEPTION CAUGHT BY FLUTTER TEST FRAMEWORK ???????????????????????????????????????????????????????????????????????????????????????????????????????????????????????????????????????????????????????????????
The following TestFailure object was thrown running a test:
  Expected: (exactly one matching node in the widget tree and Text data 'Basic Testing')
  Actual: _DescendantFinder:&lt;zero widgets with key [&lt;'Basic Testing'>] that has ancestor(s) with
type "MyHomePage" that has ancestor(s) with type "MyApp" (ignoring offstage widgets)>
   Which: means none were found but one was expected

When the exception was thrown, this was the stack:
#4      main.&lt;anonymous closure>.&lt;anonymous closure> (file:///D:/fredgrttsstuff/GithubProjects/flutter_devops/basic_coverage/test/my_home_page_test.dart:34:7)
&lt;asynchronous suspension>
&lt;asynchronous suspension>
(elided one frame from package:stack_trace)

This was caught by the test expectation on the following line:
  file:///D:/fredgrttsstuff/GithubProjects/flutter_devops/basic_coverage/test/my_home_page_test.dart line 34
The test description was:
  My home widget has a title and message, using PageObject
????????????????????????????????????????????????????????????????????????????????????????????????????????????????????????????????????????????????????????????????????????????????????????????????????????????????????????????????????????????????????????????????????????????????????????????????????????????</system-out>
    </testcase>
    <testcase classname="D:.fredgrttsstuff.GithubProjects.flutter_devops.basic_coverage.test.my_home_page" name="Has MyApp and App Title  Has user Message  My home widget  message, using PageObject" time="0.244">
      <error message="1 error, see stacktrace for details">Error:\n\nTest failed. See exception logs above.
The test description was: My home widget  message, using PageObject</error>
      <system-out>????????? EXCEPTION CAUGHT BY FLUTTER TEST FRAMEWORK ???????????????????????????????????????????????????????????????????????????????????????????????????????????????????????????????????????????????????????????????
The following TestFailure object was thrown running a test:
  Expected: (exactly one matching node in the widget tree and Text data 'You have pushed the button
this many times:')
  Actual: _DescendantFinder:&lt;zero widgets with key [&lt;'You have pushed the button this many times:'>]
that has ancestor(s) with type "MyHomePage" that has ancestor(s) with type "MyApp" (ignoring
offstage widgets)>
   Which: means none were found but one was expected

When the exception was thrown, this was the stack:
#4      main.&lt;anonymous closure>.&lt;anonymous closure>.&lt;anonymous closure> (file:///D:/fredgrttsstuff/GithubProjects/flutter_devops/basic_coverage/test/my_home_page_test.dart:43:9)
&lt;asynchronous suspension>
&lt;asynchronous suspension>
(elided one frame from package:stack_trace)

This was caught by the test expectation on the following line:
  file:///D:/fredgrttsstuff/GithubProjects/flutter_devops/basic_coverage/test/my_home_page_test.dart line 43
The test description was:
  My home widget  message, using PageObject
????????????????????????????????????????????????????????????????????????????????????????????????????????????????????????????????????????????????????????????????????????????????????????????????????????????????????????????????????????????????????????????????????????????????????????????????????????????</system-out>
    </testcase>
    <testcase classname="D:.fredgrttsstuff.GithubProjects.flutter_devops.basic_coverage.test.my_home_page" name="Has MyApp and App Title  Has user Message  User pressed add and counter changes  Ensure that when user taps add, it increments text number to one" time="0.225"/>
  </testsuite>
</testsuites>